<?xml version="1.0"?>

<robot xmlns:xacro="http://www.ros.org/wiki/xacro" name="robot_1">

  <xacro:macro name="cylinder_inertia" params="m r h">
    <inertia  ixx="${m*(3*r*r+h*h)/12}" ixy = "0" ixz = "0" iyy="${m*(3*r*r+h*h)/12}" iyz = "0" izz="${m*r*r/2}" /> 
  </xacro:macro>

  <xacro:macro name="box_inertia" params="m x y z">
    <inertia  ixx="${m*(y*y+z*z)/12}" ixy = "0" ixz = "0" iyy="${m*(x*x+z*z)/12}" iyz = "0" izz="${m*(x*x+y*y)/12}" /> 
  </xacro:macro>
      
  <xacro:macro name="sphere_inertia" params="m r">
    <inertia  ixx="${2/3*m*r*r}" ixy = "0" ixz = "0" iyy="${2/3*m*r*r}" iyz = "0" izz="${2/3*m*r*r}" /> 
  </xacro:macro>

  <xacro:macro name="sub_bloc" params="name x y z l1 l2 l3 m">
    <link name="${name}">
      <visual>
        <geometry>
          <box size="${l1} ${l2} ${l3}"/>
        </geometry>
        <origin xyz="${x} ${y} ${z}"/>
      </visual>
      <collision>
        <geometry>
          <box size="${l1} ${l2} ${l3}"/>
        </geometry>
        <origin xyz="${x} ${y} ${z}"/>
      </collision>
    <inertial>
      <mass value="${m}"/>
      <xacro:box_inertia m="${m}" x="${l1}" y="${l2}" z="${l3}" />
      <origin xyz="${x} ${y} ${z}"/>
    </inertial>
    </link>
  </xacro:macro>

  <xacro:macro name="fixed_joint" params="elem1 elem2">
    <joint name="${elem1}_to_${elem2}" type="fixed">
      <parent link="${elem1}"/>
      <child link="${elem2}"/>
    </joint>
  </xacro:macro>


  <xacro:macro name="bloc4" params="name x y z l h m ep">
    <xacro:sub_bloc name="${name}_1" x="${x}" y="${y+l/2}" z="${z+h/2}" l1="${l+ep}" l2="${ep}" l3="${h}" m="${m/4}" />
    <xacro:sub_bloc name="${name}_2" x="${x}" y="${y-l/2}" z="${z+h/2}" l1="${l+ep}" l2="${ep}" l3="${h}" m="${m/4}" />
    <xacro:sub_bloc name="${name}_3" x="${x+l/2}" y="${y}" z="${z+h/2}" l1="${ep}" l2="${l+ep}" l3="${h}" m="${m/4}" />
    <xacro:sub_bloc name="${name}_4" x="${x-l/2}" y="${y}" z="${z+h/2}" l1="${ep}" l2="${l+ep}" l3="${h}" m="${m/4}" />

    <xacro:fixed_joint elem1="${name}_1" elem2="${name}_2" />
    <xacro:fixed_joint elem1="${name}_2" elem2="${name}_3" />
    <xacro:fixed_joint elem1="${name}_3" elem2="${name}_4" />
  </xacro:macro>

  <xacro:macro name="bloc3" params="name x y z l1 l2 h m ep">
    <xacro:sub_bloc name="${name}_1" x="${x}" y="${y+l2/2}" z="${z+h/2}" l1="${l1+ep}" l2="${ep}" l3="${h}" m="${m/4}" />
    <xacro:sub_bloc name="${name}_2" x="${x}" y="${y-l2/2}" z="${z+h/2}" l1="${l1+ep}" l2="${ep}" l3="${h}" m="${m/4}" />
    <xacro:sub_bloc name="${name}_3" x="${x+l1/2}" y="${y}" z="${z+h/2}" l1="${ep}" l2="${l2+ep}" l3="${h}" m="${m/4}" />

    <xacro:fixed_joint elem1="${name}_1" elem2="${name}_2" />
    <xacro:fixed_joint elem1="${name}_2" elem2="${name}_3" />
  </xacro:macro>

  <xacro:macro name="wheel" params="name ep r m">
    <link name="wheel_${name}">
    <visual>
      <geometry>
        <cylinder length="${ep}" radius="${r}"/>
      </geometry>
    </visual>
    <collision>
      <geometry>
        <cylinder length="${ep}" radius="${r}"/>
      </geometry>
    </collision>
    <inertial>
      <mass value="${m}"/>
      <xacro:cylinder_inertia m="${m}" r="${r}" h="${ep}"/>
    </inertial>
    </link>
    <gazebo reference="wheel_${name}">
      <mu1>1.2</mu1>
      <mu2>1.2</mu2>
      <kp>500000.0</kp>
      <kd>10.0</kd>
      <minDepth>0.001</minDepth>
      <maxVel>0.1</maxVel>
      <material>Gazebo/FlatBlack</material>
    </gazebo>
  </xacro:macro>

  <link name="root_link"/>

  <joint name="root_to_bloc_1" type="fixed">
    <parent link="root_link"/>
    <child link="center_1"/>
  </joint>


  <xacro:bloc3 name="center" x="0.0" y="0.0" z="0.175" l1="0.8" l2="0.4" h="0.4" ep="0.05" m="15" />
  <xacro:bloc4 name="catcher" x="-0.375" y="0.0" z="0.175" l="0.275" h="0.3" ep="0.01" m="0.1" />
  <xacro:wheel name="left_front" r="0.20" ep="0.075" m="2"/>
  <xacro:wheel name="left_back" r="0.20" ep="0.075" m="2"/>
  <xacro:wheel name="right_front" r="0.20" ep="0.075" m="2"/>
  <xacro:wheel name="right_back" r="0.20" ep="0.075" m="2"/>


  <joint name="root_to_wheel_lf" type="continuous">
    <parent link="root_link"/>
    <child link="wheel_left_front"/>
    <origin rpy="1.57075 1.57075 0" xyz="-0.225 -0.275 0.20"/>
    <axis xyz= "0 0 1"/>
  </joint>

  <joint name="root_to_wheel_lb" type="continuous">
    <parent link="root_link"/>
    <child link="wheel_left_back"/>
    <origin rpy="1.57075 1.57075 0" xyz="0.225 -0.275 0.20"/>
    <axis xyz= "0 0 1"/>
  </joint>

  <joint name="root_to_wheel_rf" type="continuous">
    <parent link="root_link"/>
    <child link="wheel_right_front"/>
    <origin rpy="1.57075 1.57075 0" xyz="-0.225 0.275 0.20"/>
    <axis xyz= "0 0 1"/>
  </joint>

  <joint name="root_to_wheel_rb" type="continuous">
    <parent link="root_link"/>
    <child link="wheel_right_back"/>
    <origin rpy="1.57075 1.57075 0" xyz="0.225 0.275 0.20"/>
    <axis xyz= "0 0 1"/>
  </joint>

  <joint name="catcher_joint" type="prismatic">
    <parent link="root_link"/>
    <child link="catcher_1"/>
    <axis xyz="0 0 1"/>
    <limit effort="10" lower="-0.10" upper="0.0" velocity="0.5"/>
  </joint>

  <gazebo>    
  <plugin name="skid_steer_drive_controller" filename="libgazebo_ros_diff_drive.so">
    <ros>
    </ros>

    <!-- Update rate -->
    <update_rate>500</update_rate>

    <!-- Number of wheel pairs -->
    <num_wheel_pairs>2</num_wheel_pairs>
    
    <left_joint>root_to_wheel_lf</left_joint>
    <right_joint>root_to_wheel_rf</right_joint>
    <left_joint>root_to_wheel_lb</left_joint>
    <right_joint>root_to_wheel_rb</right_joint>

    <!-- kinematics -->
    <wheel_separation>0.55</wheel_separation>
    <wheel_separation>0.55</wheel_separation>

    <wheel_diameter>0.2</wheel_diameter>
    <wheel_diameter>0.2</wheel_diameter>

    <!-- limits -->
    <max_wheel_torque>20</max_wheel_torque>
    <max_wheel_acceleration>1.0</max_wheel_acceleration>

    <!-- output -->
    <publish_odom>true</publish_odom>
    <publish_odom_tf>true</publish_odom_tf>
    <publish_wheel_tf>true</publish_wheel_tf>

    <odometry_frame>odom</odometry_frame>
    <robot_base_frame>root_link</robot_base_frame>
  </plugin>

  </gazebo>
</robot>
