<?xml version="1.0"?>

<robot xmlns:xacro="http://www.ros.org/wiki/xacro" name="robot_1">

  <material name="White">
    <color rgba="1.0 1.0 1.0 1.0"/>
  </material>
  <material name="Black">
    <color rgba="0.1 0.1 0.1 1.0"/>
  </material>

  <xacro:macro name="cylinder_inertia" params="m r h">
    <inertia  ixx="${m*(3*r*r+h*h)/12}" ixy = "0" ixz = "0" iyy="${m*(3*r*r+h*h)/12}" iyz = "0" izz="${m*r*r/2}" /> 
  </xacro:macro>

  <xacro:macro name="box_inertia" params="m x y z">
    <inertia  ixx="${m*(y*y+z*z)/12}" ixy = "0" ixz = "0" iyy="${m*(x*x+z*z)/12}" iyz = "0" izz="${m*(x*x+y*y)/12}" /> 
  </xacro:macro>
      
  <xacro:macro name="sphere_inertia" params="m r">
    <inertia  ixx="${2/3*m*r*r}" ixy = "0" ixz = "0" iyy="${2/3*m*r*r}" iyz = "0" izz="${2/3*m*r*r}" /> 
  </xacro:macro>


  <xacro:macro name="sub_aruco_black" params="name x y z l h m">
    <link name="${name}">
      <visual>
        <geometry>
          <box size="${l} ${l} ${h}"/>
        </geometry>
        <origin xyz="${x} ${y} ${z}"/>
      </visual>
      <collision>
        <geometry>
          <box size="${l} ${l} ${h}"/>
        </geometry>
        <origin xyz="${x} ${y} ${z}"/>
      </collision>
    <inertial>
      <mass value="${m}"/>
      <xacro:box_inertia m="${m}" x="${l}" y="${l}" z="${h}" />
      <origin xyz="${x} ${y} ${z}"/>
    </inertial>
    </link>
    <gazebo reference="${name}">
      <material>Gazebo/Black</material>
    </gazebo>
  </xacro:macro>
  <xacro:macro name="sub_aruco_white" params="name x y z l h m">
    <link name="${name}">
      <visual>
        <geometry>
          <box size="${l} ${l} ${h}"/>
        </geometry>
        <origin xyz="${x} ${y} ${z}"/>
      </visual>
      <collision>
        <geometry>
          <box size="${l} ${l} ${h}"/>
        </geometry>
        <origin xyz="${x} ${y} ${z}"/>
      </collision>
    <inertial>
      <mass value="${m}"/>
      <xacro:box_inertia m="${m}" x="${l}" y="${l}" z="${h}" />
      <origin xyz="${x} ${y} ${z}"/>
    </inertial>
    </link>
    <gazebo reference="${name}">
      <material>Gazebo/White</material>
    </gazebo>
  </xacro:macro>

  <xacro:macro name="aruco" params="name x y z l h m">
    <xacro:sub_aruco_black name="${name}_11" x="${x-5*l/24}" y="${y-5*l/24}" z="${z}" l="${l/12}" h="${h}" m="${m}" />
    <xacro:sub_aruco_black name="${name}_12" x="${x-5*l/24}" y="${y-5*l/24+1*l/12}" z="${z}" l="${l/12}" h="${h}" m="${m}" />
    <xacro:sub_aruco_black name="${name}_13" x="${x-5*l/24}" y="${y-5*l/24+2*l/12}" z="${z}" l="${l/12}" h="${h}" m="${m}" />
    <xacro:sub_aruco_black name="${name}_14" x="${x-5*l/24}" y="${y-5*l/24+3*l/12}" z="${z}" l="${l/12}" h="${h}" m="${m}" />
    <xacro:sub_aruco_black name="${name}_15" x="${x-5*l/24}" y="${y-5*l/24+4*l/12}" z="${z}" l="${l/12}" h="${h}" m="${m}" />
    <xacro:sub_aruco_black name="${name}_16" x="${x-5*l/24}" y="${y-5*l/24+5*l/12}" z="${z}" l="${l/12}" h="${h}" m="${m}" />

    <xacro:sub_aruco_black name="${name}_21" x="${x-5*l/24+1*l/12}" y="${y-5*l/24}" z="${z}" l="${l/12}" h="${h}" m="${m}" />
    <xacro:sub_aruco_white name="${name}_22" x="${x-5*l/24+1*l/12}" y="${y-5*l/24+1*l/12}" z="${z}" l="${l/12}" h="${h}" m="${m}" />
    <xacro:sub_aruco_black name="${name}_23" x="${x-5*l/24+1*l/12}" y="${y-5*l/24+2*l/12}" z="${z}" l="${l/12}" h="${h}" m="${m}" />
    <xacro:sub_aruco_white name="${name}_24" x="${x-5*l/24+1*l/12}" y="${y-5*l/24+3*l/12}" z="${z}" l="${l/12}" h="${h}" m="${m}" />
    <xacro:sub_aruco_white name="${name}_25" x="${x-5*l/24+1*l/12}" y="${y-5*l/24+4*l/12}" z="${z}" l="${l/12}" h="${h}" m="${m}" />
    <xacro:sub_aruco_black name="${name}_26" x="${x-5*l/24+1*l/12}" y="${y-5*l/24+5*l/12}" z="${z}" l="${l/12}" h="${h}" m="${m}" />

    <xacro:sub_aruco_black name="${name}_31" x="${x-5*l/24+2*l/12}" y="${y-5*l/24}" z="${z}" l="${l/12}" h="${h}" m="${m}" />
    <xacro:sub_aruco_black name="${name}_32" x="${x-5*l/24+2*l/12}" y="${y-5*l/24+1*l/12}" z="${z}" l="${l/12}" h="${h}" m="${m}" />
    <xacro:sub_aruco_white name="${name}_33" x="${x-5*l/24+2*l/12}" y="${y-5*l/24+2*l/12}" z="${z}" l="${l/12}" h="${h}" m="${m}" />
    <xacro:sub_aruco_black name="${name}_34" x="${x-5*l/24+2*l/12}" y="${y-5*l/24+3*l/12}" z="${z}" l="${l/12}" h="${h}" m="${m}" />
    <xacro:sub_aruco_white name="${name}_35" x="${x-5*l/24+2*l/12}" y="${y-5*l/24+4*l/12}" z="${z}" l="${l/12}" h="${h}" m="${m}" />
    <xacro:sub_aruco_black name="${name}_36" x="${x-5*l/24+2*l/12}" y="${y-5*l/24+5*l/12}" z="${z}" l="${l/12}" h="${h}" m="${m}" />

    <xacro:sub_aruco_black name="${name}_41" x="${x-5*l/24+3*l/12}" y="${y-5*l/24}" z="${z}" l="${l/12}" h="${h}" m="${m}" />
    <xacro:sub_aruco_black name="${name}_42" x="${x-5*l/24+3*l/12}" y="${y-5*l/24+1*l/12}" z="${z}" l="${l/12}" h="${h}" m="${m}" />
    <xacro:sub_aruco_black name="${name}_43" x="${x-5*l/24+3*l/12}" y="${y-5*l/24+2*l/12}" z="${z}" l="${l/12}" h="${h}" m="${m}" />
    <xacro:sub_aruco_white name="${name}_44" x="${x-5*l/24+3*l/12}" y="${y-5*l/24+3*l/12}" z="${z}" l="${l/12}" h="${h}" m="${m}" />
    <xacro:sub_aruco_white name="${name}_45" x="${x-5*l/24+3*l/12}" y="${y-5*l/24+4*l/12}" z="${z}" l="${l/12}" h="${h}" m="${m}" />
    <xacro:sub_aruco_black name="${name}_46" x="${x-5*l/24+3*l/12}" y="${y-5*l/24+5*l/12}" z="${z}" l="${l/12}" h="${h}" m="${m}" />

    <xacro:sub_aruco_black name="${name}_51" x="${x-5*l/24+4*l/12}" y="${y-5*l/24}" z="${z}" l="${l/12}" h="${h}" m="${m}" />
    <xacro:sub_aruco_black name="${name}_52" x="${x-5*l/24+4*l/12}" y="${y-5*l/24+1*l/12}" z="${z}" l="${l/12}" h="${h}" m="${m}" />
    <xacro:sub_aruco_black name="${name}_53" x="${x-5*l/24+4*l/12}" y="${y-5*l/24+2*l/12}" z="${z}" l="${l/12}" h="${h}" m="${m}" />
    <xacro:sub_aruco_white name="${name}_54" x="${x-5*l/24+4*l/12}" y="${y-5*l/24+3*l/12}" z="${z}" l="${l/12}" h="${h}" m="${m}" />
    <xacro:sub_aruco_black name="${name}_55" x="${x-5*l/24+4*l/12}" y="${y-5*l/24+4*l/12}" z="${z}" l="${l/12}" h="${h}" m="${m}" />
    <xacro:sub_aruco_black name="${name}_56" x="${x-5*l/24+4*l/12}" y="${y-5*l/24+5*l/12}" z="${z}" l="${l/12}" h="${h}" m="${m}" />

    <xacro:sub_aruco_black name="${name}_61" x="${x-5*l/24+5*l/12}" y="${y-5*l/24}" z="${z}" l="${l/12}" h="${h}" m="${m}" />
    <xacro:sub_aruco_black name="${name}_62" x="${x-5*l/24+5*l/12}" y="${y-5*l/24+1*l/12}" z="${z}" l="${l/12}" h="${h}" m="${m}" />
    <xacro:sub_aruco_black name="${name}_63" x="${x-5*l/24+5*l/12}" y="${y-5*l/24+2*l/12}" z="${z}" l="${l/12}" h="${h}" m="${m}" />
    <xacro:sub_aruco_black name="${name}_64" x="${x-5*l/24+5*l/12}" y="${y-5*l/24+3*l/12}" z="${z}" l="${l/12}" h="${h}" m="${m}" />
    <xacro:sub_aruco_black name="${name}_65" x="${x-5*l/24+5*l/12}" y="${y-5*l/24+4*l/12}" z="${z}" l="${l/12}" h="${h}" m="${m}" />
    <xacro:sub_aruco_black name="${name}_66" x="${x-5*l/24+5*l/12}" y="${y-5*l/24+5*l/12}" z="${z}" l="${l/12}" h="${h}" m="${m}" />

    <xacro:fixed_joint elem1="${name}_11" elem2="${name}_12" />
    <xacro:fixed_joint elem1="${name}_12" elem2="${name}_13" />
    <xacro:fixed_joint elem1="${name}_13" elem2="${name}_14" />
    <xacro:fixed_joint elem1="${name}_14" elem2="${name}_15" />
    <xacro:fixed_joint elem1="${name}_15" elem2="${name}_16" />

    <xacro:fixed_joint elem1="${name}_16" elem2="${name}_21" />
    <xacro:fixed_joint elem1="${name}_21" elem2="${name}_22" />
    <xacro:fixed_joint elem1="${name}_22" elem2="${name}_23" />
    <xacro:fixed_joint elem1="${name}_23" elem2="${name}_24" />
    <xacro:fixed_joint elem1="${name}_24" elem2="${name}_25" />
    <xacro:fixed_joint elem1="${name}_25" elem2="${name}_26" />

    <xacro:fixed_joint elem1="${name}_26" elem2="${name}_31" />
    <xacro:fixed_joint elem1="${name}_31" elem2="${name}_32" />
    <xacro:fixed_joint elem1="${name}_32" elem2="${name}_33" />
    <xacro:fixed_joint elem1="${name}_33" elem2="${name}_34" />
    <xacro:fixed_joint elem1="${name}_34" elem2="${name}_35" />
    <xacro:fixed_joint elem1="${name}_35" elem2="${name}_36" />

    <xacro:fixed_joint elem1="${name}_36" elem2="${name}_41" />
    <xacro:fixed_joint elem1="${name}_41" elem2="${name}_42" />
    <xacro:fixed_joint elem1="${name}_42" elem2="${name}_43" />
    <xacro:fixed_joint elem1="${name}_43" elem2="${name}_44" />
    <xacro:fixed_joint elem1="${name}_44" elem2="${name}_45" />
    <xacro:fixed_joint elem1="${name}_45" elem2="${name}_46" />

    <xacro:fixed_joint elem1="${name}_46" elem2="${name}_51" />
    <xacro:fixed_joint elem1="${name}_51" elem2="${name}_52" />
    <xacro:fixed_joint elem1="${name}_52" elem2="${name}_53" />
    <xacro:fixed_joint elem1="${name}_53" elem2="${name}_54" />
    <xacro:fixed_joint elem1="${name}_54" elem2="${name}_55" />
    <xacro:fixed_joint elem1="${name}_55" elem2="${name}_56" />

    <xacro:fixed_joint elem1="${name}_56" elem2="${name}_61" />
    <xacro:fixed_joint elem1="${name}_61" elem2="${name}_62" />
    <xacro:fixed_joint elem1="${name}_62" elem2="${name}_63" />
    <xacro:fixed_joint elem1="${name}_63" elem2="${name}_64" />
    <xacro:fixed_joint elem1="${name}_64" elem2="${name}_65" />
    <xacro:fixed_joint elem1="${name}_65" elem2="${name}_66" />


  </xacro:macro>


  <xacro:macro name="sub_bloc" params="name x y z l1 l2 l3 m">
    <link name="${name}">
      <visual>
        <geometry>
          <box size="${l1} ${l2} ${l3}"/>
        </geometry>
        <origin xyz="${x} ${y} ${z}"/>
      </visual>
      <collision>
        <geometry>
          <box size="${l1} ${l2} ${l3}"/>
        </geometry>
        <origin xyz="${x} ${y} ${z}"/>
      </collision>
    <inertial>
      <mass value="${m}"/>
      <xacro:box_inertia m="${m}" x="${l1}" y="${l2}" z="${l3}" />
      <origin xyz="${x} ${y} ${z}"/>
    </inertial>
    </link>
    <gazebo reference="${name}">
      <material>Gazebo/Grey</material>
    </gazebo>

  </xacro:macro>

  <xacro:macro name="fixed_joint" params="elem1 elem2">
    <joint name="${elem1}_to_${elem2}" type="fixed">
      <parent link="${elem1}"/>
      <child link="${elem2}"/>
    </joint>
  </xacro:macro>


  <xacro:macro name="bloc5" params="name x y z l h m ep">
    <xacro:sub_bloc name="${name}_1" x="${x}" y="${y+l/2}" z="${z+h/2}" l1="${l+ep}" l2="${ep}" l3="${h}" m="${m/5}" />
    <xacro:sub_bloc name="${name}_2" x="${x}" y="${y-l/2}" z="${z+h/2}" l1="${l+ep}" l2="${ep}" l3="${h}" m="${m/5}" />
    <xacro:sub_bloc name="${name}_3" x="${x+l/2}" y="${y}" z="${z+h/2}" l1="${ep}" l2="${l+ep}" l3="${h}" m="${m/5}" />
    <xacro:sub_bloc name="${name}_4" x="${x-l/2}" y="${y}" z="${z+h/2}" l1="${ep}" l2="${l+ep}" l3="${h}" m="${m/5}" />
    <xacro:sub_bloc name="${name}_5" x="${x}" y="${y}" z="${z+h+ep/2}" l1="${l+ep}" l2="${l+ep}" l3="${ep}" m="${m/5}" />

    <xacro:fixed_joint elem1="${name}_1" elem2="${name}_2" />
    <xacro:fixed_joint elem1="${name}_2" elem2="${name}_3" />
    <xacro:fixed_joint elem1="${name}_3" elem2="${name}_4" />
    <xacro:fixed_joint elem1="${name}_4" elem2="${name}_5" />
  </xacro:macro>

  <xacro:macro name="bloc4" params="name x y z l1 l2 h m ep">
    <xacro:sub_bloc name="${name}_1" x="${x}" y="${y+l2/2}" z="${z+h/2}" l1="${l1+ep}" l2="${ep}" l3="${h}" m="${m/4}" />
    <xacro:sub_bloc name="${name}_2" x="${x}" y="${y-l2/2}" z="${z+h/2}" l1="${l1+ep}" l2="${ep}" l3="${h}" m="${m/4}" />
    <xacro:sub_bloc name="${name}_3" x="${x+l1/2}" y="${y}" z="${z+h/2}" l1="${ep}" l2="${l2+ep}" l3="${h}" m="${m/4}" />
    <xacro:sub_bloc name="${name}_4" x="${x}" y="${y}" z="${z+h+ep/2}" l1="${l1+ep}" l2="${l2+ep}" l3="${ep}" m="${m/4}" />

    <xacro:aruco name="${name}_aruco" x="${x}" y="${y}" z="${z+h+ep}" l="0.8" h="0.001" m="${m/1000}" />

    <xacro:fixed_joint elem1="${name}_1" elem2="${name}_2" />
    <xacro:fixed_joint elem1="${name}_2" elem2="${name}_3" />
    <xacro:fixed_joint elem1="${name}_3" elem2="${name}_4" />
    <xacro:fixed_joint elem1="${name}_4" elem2="${name}_aruco_11" />
  </xacro:macro>

  <xacro:macro name="camera_xacro" params="name">
  <link name="${name}">
    <collision>
      <origin xyz="0 0 0" rpy="0 0 0"/>
      <geometry>
    <box size="0.005 0.005 0.005"/>
      </geometry>
    </collision>

    <visual>
      <origin xyz="0 0 0" rpy="0 0 0"/>
      <geometry>
    <box size="0.005 0.005 0.005"/>
      </geometry>
      <material name="red"/>
    </visual>

    <inertial>
      <mass value="1e-5" />
      <origin xyz="0 0 0" rpy="0 0 0"/>
      <inertia ixx="1e-6" ixy="0" ixz="0" iyy="1e-6" iyz="0" izz="1e-6" />
    </inertial>
  </link>
  </xacro:macro>


  <xacro:macro name="wheel" params="name ep r m">
    <link name="wheel_${name}">
    <visual>
      <geometry>
        <cylinder length="${ep}" radius="${r}"/>
      </geometry>
    </visual>
    <collision>
      <geometry>
        <cylinder length="${ep}" radius="${r}"/>
      </geometry>
    </collision>
    <inertial>
      <mass value="${m}"/>
      <xacro:cylinder_inertia m="${m}" r="${r}" h="${ep}"/>
    </inertial>
    </link>
    <gazebo reference="wheel_${name}">
      <mu1>1.2</mu1>
      <mu2>1.2</mu2>
      <kp>500000.0</kp>
      <kd>10.0</kd>
      <minDepth>0.001</minDepth>
      <maxVel>0.1</maxVel>
      <material>Gazebo/FlatBlack</material>
    </gazebo>
  </xacro:macro>

  <link name="root_link"/>

  <joint name="root_to_bloc_1" type="fixed">
    <parent link="root_link"/>
    <child link="center_1"/>
  </joint>






  <xacro:bloc4 name="center" x="0.0" y="0.0" z="0.175" l1="0.8" l2="0.4" h="0.4" ep="0.05" m="10" />
  <xacro:bloc5 name="catcher" x="-0.375" y="0.0" z="0.175" l="0.275" h="0.3" ep="0.01" m="3" />
  <xacro:wheel name="left_front" r="0.20" ep="0.15" m="3"/>
  <xacro:wheel name="left_back" r="0.20" ep="0.15" m="3"/>
  <xacro:wheel name="right_front" r="0.20" ep="0.15" m="3"/>
  <xacro:wheel name="right_back" r="0.20" ep="0.15" m="3"/>

  <xacro:camera_xacro name="camera1_link" />
  <xacro:camera_xacro name="camera2_link" />




  <gazebo reference="camera1_link">
    <sensor name="camera1" type="camera">
        <always_on>1</always_on>
        <update_rate>10</update_rate>
        <visualize>false</visualize>

        <camera name="camera1">
            <horizontal_fov>1</horizontal_fov>
            <image>
                <width>800</width>
                <height>800</height>
            </image>
            <clip>
                <near>0.02</near>
                <far>300</far>
            </clip>
        </camera>
        <plugin name="camera1_controller" filename="libgazebo_ros_camera.so">
            <camera_name>camera1</camera_name>
            <hack_baseline>0.07</hack_baseline>
        </plugin>

    </sensor>
  </gazebo>

  <gazebo reference="camera2_link">
    <sensor name="camera2" type="camera">
        <always_on>1</always_on>
        <update_rate>10</update_rate>
        <visualize>false</visualize>

        <camera name="camera2">
            <horizontal_fov>1</horizontal_fov>
            <image>
                <width>800</width>
                <height>800</height>
            </image>
            <clip>
                <near>0.02</near>
                <far>300</far>
            </clip>
        </camera>
        <plugin name="camera2_controller" filename="libgazebo_ros_camera.so">
            <camera_name>camera2</camera_name>
            <hack_baseline>0.07</hack_baseline>
        </plugin>

    </sensor>
  </gazebo>

  <joint name="catcher_to_cam1" type="fixed">
    <parent link="catcher_5"/>
    <child link="camera1_link"/>
    <origin rpy="0 1.57075 0" xyz="-0.375 0 0.475"/>
    <axis xyz= "0 0 1"/>
  </joint>

  <joint name="catcher_to_cam2" type="fixed">
    <parent link="catcher_5"/>
    <child link="camera2_link"/>
    <origin rpy="0 2 0" xyz="-0.525 0 0.475"/>
    <axis xyz= "0 0 1"/>
  </joint>

  <joint name="root_to_wheel_lf" type="continuous">
    <parent link="root_link"/>
    <child link="wheel_left_front"/>
    <origin rpy="1.57075 1.57075 0" xyz="-0.225 -0.350 0.20"/>
    <axis xyz= "0 0 1"/>
  </joint>

  <joint name="root_to_wheel_lb" type="continuous">
    <parent link="root_link"/>
    <child link="wheel_left_back"/>
    <origin rpy="1.57075 1.57075 0" xyz="0.225 -0.350 0.20"/>
    <axis xyz= "0 0 1"/>
  </joint>

  <joint name="root_to_wheel_rf" type="continuous">
    <parent link="root_link"/>
    <child link="wheel_right_front"/>
    <origin rpy="1.57075 1.57075 0" xyz="-0.225 0.350 0.20"/>
    <axis xyz= "0 0 1"/>
  </joint>

  <joint name="root_to_wheel_rb" type="continuous">
    <parent link="root_link"/>
    <child link="wheel_right_back"/>
    <origin rpy="1.57075 1.57075 0" xyz="0.225 0.350 0.20"/>
    <axis xyz= "0 0 1"/>
  </joint>

  <joint name="catcher_joint" type="prismatic">
    <parent link="root_link"/>
    <child link="catcher_1"/>
    <axis xyz="0 0 1"/>
    <limit effort="10" lower="-0.10" upper="0.0" velocity="0.5"/>
  </joint>

  <gazebo>  
    <plugin name="skid_steer_drive_controller" filename="libgazebo_ros_diff_drive.so">
      <ros>
      </ros>

      <!-- Update rate -->
      <update_rate>500</update_rate>

      <!-- Number of wheel pairs -->
      <num_wheel_pairs>2</num_wheel_pairs>
      
      <left_joint>root_to_wheel_lf</left_joint>
      <right_joint>root_to_wheel_rf</right_joint>
      <left_joint>root_to_wheel_lb</left_joint>
      <right_joint>root_to_wheel_rb</right_joint>

      <!-- kinematics -->
      <wheel_separation>0.55</wheel_separation>
      <wheel_separation>0.55</wheel_separation>

      <wheel_diameter>0.2</wheel_diameter>
      <wheel_diameter>0.2</wheel_diameter>

      <!-- limits -->
      <max_wheel_torque>20</max_wheel_torque>
      <max_wheel_acceleration>0.5</max_wheel_acceleration>

      <!-- output -->
      <publish_odom>true</publish_odom>
      <publish_odom_tf>true</publish_odom_tf>
      <publish_wheel_tf>true</publish_wheel_tf>

      <odometry_frame>odom</odometry_frame>
      <robot_base_frame>root_link</robot_base_frame>
    </plugin>

    <plugin name="gazebo_ros_force" filename="libgazebo_ros_force.so">
        <ros>
          <remapping>gazebo_ros_force:=catcher_force</remapping>
        </ros>
        <link_name>catcher_1</link_name>
        <force_frame>world</force_frame>
    </plugin>
  </gazebo>

</robot>
